Workbook

Sheet Executive Summary
A1: PropertyAgent CRM - Cost Reduction & Remediation Proposal
A2: Prepared 10 August 2026 | All figures in Malaysian Ringgit | Tools and services only
B4: RECOMMENDATION
B5: Replace the two paid-service dependencies - the hosted database and the Clerk authentication service - with free equivalents we control. Both are free at our size, and the application was deliberately built so that each swap touches a single component. RECOMMENDATION: OPTION D - a server we run ourselves, inside Malaysia. At RM 92 a month it is cheaper than the managed alternatives, gives the largest specification of the four (2 processors, 4 GB memory, 100 GB disk), and keeps all client records - including identity-card numbers - inside Malaysia, which closes the PDPA data-residency question rather than deferring it. It is recommended on the basis that we have in-house IT capability to run it; the trade-off is that backups, security patching and uptime become our responsibility rather than a vendor's. Fallback: Option A if we would rather a vendor carried the operational work, or Option B if minimum cost is the priority. The finding that matters most is not about cost at all: the free hosting tier in use today is licensed for non-commercial personal use only, and the review found seven Critical or High security and data-loss faults - including one where any agent can view any client's identity-card number. Those need fixing whichever option is chosen.
B7: AT A GLANCE
B8: Measure | C8: Option A Managed | D8: Option B Lowest cost | E8: Option C Singapore VPS | F8: Option D Malaysia only | G8: Comment
B9: Cost - MYR per month | C9: ='Cost Comparison'!D14 -> 102 | D9: ='Cost Comparison'!E14 -> 30.75 | E9: ='Cost Comparison'!F14 -> 64 | F9: ='Cost Comparison'!G14 -> 92 | G9: Option B needs the deployment configuration repaired first.
B10: Cost - MYR per year | C10: ='Cost Comparison'!G15 -> 1104 | D10: ='Cost Comparison'!E15 -> 369 | E10: ='Cost Comparison'!F15 -> 768 | F10: ='Cost Comparison'!G15 -> 1104
B11: Cost over three years | C11: ='Cost Comparison'!D16 -> 3672 | D11: ='Cost Comparison'!E16 -> 1107 | E11: ='Cost Comparison'!F16 -> 2304 | F11: ='Cost Comparison'!G16 -> 3312 | G11: Subscriptions only. No hardware, licences or contractors are being purchased.
B12: Who runs and maintains it | C12: Supabase + Vercel | D12: Supabase + Cloudflare | E12: Ourselves | F12: Ourselves | G12: Options C and D rent a bare server only - backups, patching and uptime become ours.
B13: Client data stored in | C13: Singapore | D13: Singapore | E13: Singapore | F13: MALAYSIA | G13: See the Data Residency tab.
B15: WHAT WE ARE ASKING FOR
B16: Item | C16: Value
B17: Recurring cost to approve - per month | C17: ='Cost Comparison'!G14 -> 92 | D17: Option D, the recommended option.
B18: Recurring cost to approve - per year | C18: ='Cost Comparison'!G15 -> 1104 | D18: The entire monetary request.
B19: Cost over three years | C19: ='Cost Comparison'!G16 -> 3312 | D19: Assuming the exchange rate holds.
B20: One-off purchases required | C20: ='Cost Comparison'!D15*0 -> 0 | D20: None - no hardware, licences or contractors.
B21: Critical and High findings to close | C21: ='Risks & Findings'!$D$20 -> 7 | D21: Independent of the hosting decision.
B23: POINTS FOR MANAGEMENT ATTENTION
B24: - The tools this system runs on cost under RM 1,300 a year. Cost is not the issue; the security findings below are.
B25: - The system has verified security gaps today: any agent can view any client's identity-card number, and one public endpoint is open to the internet. These are closed in the first two phases and are unrelated to cost.
B26: - Our current free hosting tier is not licensed for commercial use. This needs correcting whichever option is approved.
B27: - The 24-month PDPA data-purge routine exists in the system but nothing schedules it, so it is not currently being carried out.
B28: - Client identity numbers would sit in Singapore under Options A to C. Option D keeps all data in Malaysia at no extra cost, but makes backups and uptime our own responsibility. Worth confirming the requirement with a qualified adviser.
B29: - The four options differ by under RM 900 a year. The decision should be made on compliance, data residency and who carries responsibility for the server - not on the subscription figure.
B31: Legend: blue = editable input black = calculated green = pulled from another tab yellow = key assumption to confirm
B33: WHY OPTION D
B34: Reason | C34: Detail
B35: Cheaper than managed | C35: RM 92 a month against RM 102 for Option A, and RM 1,104 a year against RM 1,224.
B36: Largest specification | C36: 2 processors, 4 GB dedicated memory and 100 GB disk. Supabase Pro at RM 119 a month gives 1 GB memory and 8 GB disk - less, for more.
B37: Solves data residency | C37: All client records including identity-card numbers stay in Malaysia. No managed provider offers a Malaysia region, so this cannot be achieved any other way.
B38: Lowest latency | C38: The server sits in Malaysia rather than Singapore - the fastest option for agents working locally.
B39: No capacity ceiling | C39: The free database plan caps at 500 MB. Our own server has no vendor limit, so the question never arises again.
B40: We have the capability | C40: Managing the server in-house is realistic for us. This is the assumption the recommendation rests on - if it changes, Option A becomes the answer.
B41: CONDITION OF APPROVAL: Option D is recommended on the condition that automated database backups are set up AND a restore is tested before the system carries live client data. Running our own server means no vendor does this for us. It is roughly half a day of work and it is not optional.

Sheet Cost Comparison
A1: Running Cost - Tools & Services Only (MYR)
A2: Hosting, database, storage and subscriptions. Internal development effort is not included.
B4: Component | C4: Current (as-is) | D4: Option A Managed | E4: Option B Lowest cost | F4: Option C Self-hosted Singapore | G4: Option D Malaysia only (residency) (recommended) | H4: Note
B5: Database | C5: 0 | D5: 0 | E5: 0 | F5: 0 | G5: 0 | H5: Neon free tier today. A and B use Supabase Free in Singapore. C and D run PostgreSQL on our own server, included in the server line.
B6: Application hosting | C6: 0 | D6: =20*'Assumptions & Sources'!$C$6 -> 95 | E6: =5*'Assumptions & Sources'!$C$6 -> 23.75 | F6: =12*'Assumptions & Sources'!$C$6 -> 57 | G6: 60 | H6: Today's RM 0 is Vercel's non-commercial tier - see the note below. D is an Exabytes 4 GB server in Malaysia running both the application and the database.
B7: Authentication | C7: 0 | D7: 0 | E7: 0 | F7: 0 | G7: 0 | H7: Clerk free tier today. Better Auth is free and self-hosted in every proposed option.
B8: File storage (photos) | C8: 0 | D8: 0 | E8: 0 | F8: 0 | G8: 0 | H8: Cloudflare R2 - 10 GB free, no egress charges. Under Option D photographs move to the Malaysian server's own disk.
B9: Off-site backup storage | C9: 0 | D9: 0 | E9: 0 | F9: 0 | G9: 25 | H9: A to C back up into the free Cloudflare allowance. Option D needs a Malaysian backup target - estimate.
B10: Transactional email | C10: 0 | D10: 0 | E10: 0 | F10: 0 | G10: 0 | H10: Resend free tier.
B11: Error monitoring | C11: 0 | D11: 0 | E11: 0 | F11: 0 | G11: 0 | H11: Sentry free tier.
B12: AI development assistant | C12: 0 | D12: 0 | E12: 0 | F12: 0 | G12: 0 | H12: Existing company subscription - no incremental cost attributed. Enter a monthly figure here if it should be charged to this project.
B13: Domain name | C13: 7 | D13: 7 | E13: 7 | F13: 7 | G13: 7 | H13: Existing cost, unchanged.
B14: TOTAL COST - MYR per month | C14: =SUM(C5:C13) -> 7 | D14: =SUM(D5:D13) -> 102 | E14: =SUM(E5:E13) -> 30.75 | F14: =SUM(F5:F13) -> 64 | G14: =SUM(G5:G13) -> 92
B15: TOTAL COST - MYR per year | C15: =C14*12 -> 84 | D15: =D14*12 -> 1224 | E15: =E14*12 -> 369 | F15: =F14*12 -> 768 | G15: =G14*12 -> 1104
B16: TOTAL COST - MYR over three years | C16: =C15*3 -> 252 | D16: =D15*3 -> 3672 | E16: =E15*3 -> 1107 | F16: =F15*3 -> 2304 | G16: =G15*3 -> 3312
B17: Equivalent USD per month | C17: =C14/'Assumptions & Sources'!$C$6 -> 1.4736842 | D17: =D14/'Assumptions & Sources'!$C$6 -> 21.473684 | E17: =E14/'Assumptions & Sources'!$C$6 -> 6.4736842 | F17: =F14/'Assumptions & Sources'!$C$6 -> 13.473684 | G17: =G14/'Assumptions & Sources'!$C$6 -> 19.368421
B19: QUALITATIVE COMPARISON
B20: Factor | C20: Current | D20: Option A | E20: Option B | F20: Option C | G20: Option D
B21: Commercially licensed | C21: NO | D21: Yes | E21: Yes | F21: Yes | G21: Yes
B22: Where client data is stored | C22: Outside Malaysia | D22: Singapore | E22: Singapore | F22: Singapore | G22: MALAYSIA
B23: Who runs the database | C23: Neon | D23: Supabase | E23: Supabase | F23: Ourselves | G23: Ourselves
B24: Who takes the backups | C24: Neon | D24: Supabase | E24: Supabase | F24: Ourselves | G24: Ourselves
B25: Who patches the server | C25: Vercel | D25: Vercel | E25: Cloudflare | F25: Ourselves | G25: Ourselves
B26: Latency from Kuala Lumpur | C26: Good | D26: Good | E26: Good | F26: Good | G26: Best
B28: WHY 'CURRENT' IS NOT REALLY FREE. Vercel's Hobby plan, which hosts the application today, is licensed for non-commercial personal use only. A CRM the agency runs its business on is commercial use. Correcting this is the single largest cash line in the proposal, and it is a compliance obligation rather than an optional upgrade.
B29: WHO THE VENDORS ARE
B30: Service | C30: Who provides it | D30: Where they are | E30: What they are responsible for
B31: Database - today | C31: Neon | D31: United States | E31: Runs the PostgreSQL database, backups and uptime. REPLACED under every option.
B32: Authentication - today | C32: Clerk | D32: United States | E32: Handles staff log-in. REPLACED by Better Auth, which we run ourselves, under every option.
B33: Hosting - today | C33: Vercel (free tier) | D33: United States | E33: Runs the web application. Free tier is not licensed for commercial use - see below.
B34: Database - Options A and B | C34: Supabase | D34: Singapore region | E34: Runs PostgreSQL, takes backups, keeps it online. We only connect to it.
B35: Hosting - Option A | C35: Vercel (paid) | D35: Global network | E35: Runs the web application, deployments and scaling.
B36: Hosting - Option B | C36: Cloudflare | D36: Global network | E36: Same role as Vercel, on a cheaper plan.
B37: Server - Option C | C37: DigitalOcean or Vultr | D37: Singapore | E37: Supplies a bare server and network only. Everything above that - PostgreSQL, the application, backups, security updates - is OURS.
B38: Server - Option D | C38: Exabytes | D38: Malaysia | E38: Same as Option C: bare server only. All software and backups are OURS.
B39: Photo storage - all options | C39: Cloudflare R2 | D39: Global network | E39: Stores property photographs. Free at our volume.
B40: Email / monitoring | C40: Resend / Sentry | D40: United States | E40: Send notification emails and report faults. Both free at our volume.
B42: The key distinction: Supabase, Vercel and Cloudflare are MANAGED services - they run the software and carry responsibility for backups, security patching and uptime. DigitalOcean, Vultr and Exabytes only rent us a bare machine. Under Options C and D nobody but us installs updates, checks that backups actually restore, or gets out of bed when the server stops. That is the real difference between the options, not the price.
B45: FREE-TIER REALITY CHECK (Options A and B)
B46: Question | C46: Answer
...

Sheet What Each Option Includes
A1: What Each Option Actually Includes
A2: Component by component: who provides it, where it sits, what it costs, and who is responsible when it breaks.
B4: OPTION A - Managed (Supabase + Vercel)
B5: Everything is run by a vendor. Lowest demand on your time.
B6: Component | C6: Provided by | D6: Where it sits | E6: MYR / month | F6: Responsible when it breaks | G6: What is included
B7: Database | C7: Supabase (free tier) | D7: Singapore | E7: 0 | F7: Supabase | G7: PostgreSQL run and patched by Supabase. Free plan: 500 MB database, 500 MB shared RAM, community support only, NO SLA, and the project pauses after 7 days of no activity. Commercial use is permitted - unlike Vercel's free tier - but it is unsupported.
B8: Application hosting | C8: Vercel (Pro plan) | D8: Global network | E8: =20*'Assumptions & Sources'!$C$6 -> 95 | F8: Vercel | G8: Runs the website, deployments, scaling and SSL certificates. One deploying seat.
B9: Staff log-in | C9: Better Auth | D9: Our own database | E9: 0 | F9: Ourselves | G9: Free open-source software running inside our own application. No vendor, no per-user fee.
B10: Property photographs | C10: Cloudflare R2 | D10: Global network | E10: 0 | F10: Cloudflare | G10: 10 GB free, no download charges. Already in use today.
B11: Backups | C11: Ourselves | D11: Wherever we send it | E11: 0 | F11: Ourselves | G11: NOT INCLUDED on the Supabase free plan. Supabase's own documentation tells free-plan users to export regularly themselves. We must schedule our own dump and test that it restores.
B12: Notification email | C12: Resend | D12: United States | E12: 0 | F12: Resend | G12: Free tier, roughly 3,000 messages a month.
B13: Fault reporting | C13: Sentry | D13: United States | E13: 0 | F13: Sentry | G13: Free tier. Needs to be switched on properly - it is installed but inactive today.
B14: Domain name | C14: Existing registrar | D14: - | E14: 7 | F14: Ourselves | G14: Unchanged.
B15: TOTAL | E15: =SUM(E7:E14) -> 102 | G15: Per month, tools and services only.
B16: What this buys us: Vendor handles all patching, backups and uptime | No server to look after | Fastest to set up - nothing to provision
B17: What we take on: Most expensive of the four, though only by about RM 40 a month | Client data sits in Singapore, not Malaysia | Vercel bills per deploying seat if more developers are added
B20: OPTION B - Lowest cost (Supabase + Cloudflare)
B21: Same as Option A, with cheaper hosting.
B22: Component | C22: Provided by | D22: Where it sits | E22: MYR / month | F22: Responsible when it breaks | G22: What is included
B23: Database | C23: Supabase (free tier) | D23: Singapore | E23: 0 | F23: Supabase | G23: PostgreSQL run and patched by Supabase. Free plan: 500 MB database, 500 MB shared RAM, community support only, NO SLA, and the project pauses after 7 days of no activity. Commercial use is permitted - unlike Vercel's free tier - but it is unsupported.
B24: Application hosting | C24: Cloudflare Workers | D24: Global network | E24: =5*'Assumptions & Sources'!$C$6 -> 23.75 | F24: Cloudflare | G24: Same role as Vercel at a quarter of the price. The deployment configuration for this is currently incomplete and must be repaired first.
B25: Staff log-in | C25: Better Auth | D25: Our own database | E25: 0 | F25: Ourselves | G25: As Option A.
B26: Property photographs | C26: Cloudflare R2 | D26: Global network | E26: 0 | F26: Cloudflare | G26: As Option A - and same vendor as the hosting, which simplifies billing.
B27: Backups | C27: Ourselves | D27: Wherever we send it | E27: 0 | F27: Ourselves | G27: NOT INCLUDED on the Supabase free plan. Supabase's own documentation tells free-plan users to export regularly themselves. We must schedule our own dump and test that it restores.
B28: Notification email | C28: Resend | D28: United States | E28: 0 | F28: Resend | G28: As Option A.
B29: Fault reporting | C29: Sentry | D29: United States | E29: 0 | F29: Sentry | G29: As Option A.
B30: Domain name | C30: Existing registrar | D30: - | E30: 7 | F30: Ourselves | G30: Unchanged.
B31: TOTAL | E31: =SUM(E23:E30) -> 30.75 | G31: Per month, tools and services only.
B32: What this buys us: Cheapest option by a clear margin | Vendor still handles patching, backups and uptime | Hosting and photo storage under one vendor
B33: What we take on: The Cloudflare deployment setup is broken today and needs fixing before this works | Cloudflare imposes tighter limits on how long a page may take to build | Client data still sits in Singapore
B36: OPTION C - Self-hosted, Singapore (DigitalOcean or Vultr)
B37: We rent a bare server. Everything on it is ours.
B38: Component | C38: Provided by | D38: Where it sits | E38: MYR / month | F38: Responsible when it breaks | G38: What is included
B39: Server | C39: DigitalOcean or Vultr | D39: Singapore | E39: =12*'Assumptions & Sources'!$C$6 -> 57 | F39: Ourselves | G39: 2 GB machine. The vendor supplies hardware, network and power - nothing else.
B40: Database | C40: PostgreSQL, self-installed | D40: On our server | E40: 0 | F40: Ourselves | G40: No size limit and no vendor. We install, tune, patch and back it up.
B41: Application hosting | C41: Our server | D41: Singapore | E41: 0 | F41: Ourselves | G41: We run the application, renew SSL certificates and handle deployments.
B42: Staff log-in | C42: Better Auth | D42: Our own database | E42: 0 | F42: Ourselves | G42: As Option A.
B43: Property photographs | C43: Cloudflare R2 | D43: Global network | E43: 0 | F43: Cloudflare | G43: Kept on R2 - free and simpler than storing on the server.
B44: Backups | C44: Ourselves, into Cloudflare R2 | D44: Global network | E44: 0 | F44: Ourselves | G44: Must be set up and, importantly, test-restored. Nothing is automatic.
B45: Notification email | C45: Resend | D45: United States | E45: 0 | F45: Resend | G45: As Option A.
...

Sheet Specification Comparison
A1: Specification Comparison - Like for Like
A2: Answering the question: is the cheaper option cheaper because it gives us less?
B4: SHORT ANSWER. No - Option B is not cheaper because it is a smaller machine. Options A and B do not rent us a machine at all: they charge per request served, and the vendor supplies whatever capacity each request needs. Vercel charges USD 20 per developer seat whether we serve ten requests or ten million; Cloudflare charges a USD 5 floor that already covers ten million requests. At our size we are paying Vercel for a team platform, not for capacity. There IS one genuine specification difference, and it is set out in red below: Cloudflare gives 128 MB of memory per request against Vercel's 2 GB. That is a real constraint - it is just far above what this application needs.
B6: 1. THESE ARE TWO DIFFERENT KINDS OF PRODUCT
C7: Options A and B - pay per request | E7: Options C and D - rent a machine
B8: How capacity works | C8: No fixed machine. Each request gets its own short-lived slice of capacity, and thousands can run side by side. | E8: One fixed machine. Every request, plus the database, shares the same processor and memory.
B9: If traffic doubles | C9: Nothing to do. It scales by itself and we pay a little more. | E9: We must resize the server ourselves, and pay for the larger size all month.
B10: If traffic is almost zero | C10: We still pay the plan minimum, but nothing more. | E10: We pay for the whole machine regardless - it sits idle.
B11: What the price buys | C11: Vercel: a developer platform, per seat. Cloudflare: capacity, per request. | E11: Hardware, network and power. Nothing else.
B13: 2. SPECIFICATION, SIDE BY SIDE
B14: Specification | C14: Option A Vercel Pro | D14: Option B Cloudflare Workers | E14: Option C DigitalOcean / Vultr | F14: Option D Exabytes C2 | G14: Comment
B15: Cost per month | C15: RM 95 | D15: RM 24 | E15: RM 57 | F15: RM 60 | G15: Hosting line only, excluding database and domain.
B16: Memory | C16: 2 GB per request (up to 4 GB) | D16: 128 MB per request | E16: 2 GB total, shared with database | F16: 4 GB total, shared with database | G16: THE ONE REAL SPEC GAP. Cloudflare's 128 MB is a hard ceiling per request - but it is memory per request, not for the whole system, and thousands of requests run in parallel.
B17: Processor | C17: 1 vCPU per request (up to 2) | D17: Metered CPU time, 30M ms included | E17: 1 vCPU total | F17: 2 vCPU total | G17: A and B give each request its own processor slice. C and D share one processor across everything, including the database.
B18: Max time per request | C18: 300 seconds (up to 800) | D18: 30 seconds of CPU (up to 5 minutes) | E18: Ours to set | F18: Ours to set | G18: Our slowest page is a report query measured in hundreds of milliseconds. Not a constraint.
B19: Requests included | C19: 10 million / month | D19: 10 million / month | E19: No vendor limit | F19: No vendor limit | G19: C and D are limited by the machine, not by a plan.
B20: Data transfer included | C20: 1 TB / month | D20: No egress charge | E20: 2 TB / month | F20: 4 TB / month | G20: Cloudflare not charging for egress is a genuine structural advantage.
B21: Disk storage | C21: 50 GB blob storage | D21: 10 GB free on R2 | E21: ~50 GB SSD | F21: 100 GB NVMe | G21: On C and D the disk also holds the database and, on D, the property photographs.
B22: Automatic scaling | C22: Yes, to 30,000 concurrent | D22: Yes, effectively unlimited | E22: No - we resize manually | F22: No - we resize manually | G22: Irrelevant at five users, but it is the reason A and B need no capacity planning.
B23: Runtime environment | C23: Full Node.js | D23: V8 isolates, not Node.js | E23: Full Node.js | F23: Full Node.js | G23: THE REAL CATCH WITH B. Next.js does not run natively on Cloudflare; it needs the OpenNext adapter, which is incomplete in our repository today.
B24: Who patches it | C24: Vercel | D24: Cloudflare | E24: Ourselves | F24: Ourselves
B25: If we exceed the plan | C25: Overage charged per GB | D25: USD 0.30 per extra million requests | E25: Site slows, then falls over | F25: Site slows, then falls over | G25: A and B degrade financially. C and D degrade operationally - which is worse at 9am on a Monday.
B27: 3. WHAT WE ACTUALLY NEED (blue cells are estimates - adjust them)
B28: Measure | C28: Our estimated need | D28: Option A provides | E28: Option B provides | F28: Headroom (A / B) | G28: Comment
B29: Requests per month | C29: 50000 | D29: 10000000 | E29: 10000000 | F29: =D29/$C29&"x / "&TEXT(E29/$C29,"0")&"x" -> 200x / 200x | G29: Five agents at roughly 300 page views each per working day, plus web-form submissions.
B30: Data transfer, GB per month | C30: 10 | D30: 1000 | E30: 1000 | F30: =D30/$C30&"x / "&TEXT(E30/$C30,"0")&"x" -> 100x / 100x | G30: Mostly property photographs. Cloudflare does not charge for this at all.
B31: Peak memory per request, MB | C31: 64 | D31: 2048 | E31: 128 | F31: =D31/$C31&"x / "&TEXT(E31/$C31,"0")&"x" -> 32x / 2x | G31: A Next.js page render. Comfortably inside Cloudflare's 128 MB, but with less spare room than Vercel.
B33: VERDICT. On every measure that matters to this application, all four options are enormously over-provisioned - we would need roughly two hundred times our expected traffic before any plan limit came into view. So the cheaper option is not cheaper because it gives us less capacity; it is cheaper because Cloudflare sells capacity by the request while Vercel sells a platform by the developer seat. The two things that should decide between them are not on the price line at all: (1) Cloudflare's 128 MB memory ceiling is real, though roughly double what a page render of ours needs; (2) Cloudflare does not run Node.js, so Next.js needs a translation layer that is currently incomplete in our code - that is a day of work and a permanently less-travelled path. Worth noting for the residency discussion: Option D gives us the largest specification of all four - 2 processors and 4 GB of dedicated memory - for less than Vercel costs. Its cost is not capacity, it is that we do the patching.
B35: Sources: vercel.com/docs/functions/limitations | fencode.dev Vercel Free vs Pro 2026 | developers.cloudflare.com/workers/platform/limits | developers.cloudflare.com/workers/platform/pricing | cloudmart.dev/blog/cheapest-vps-2026 | exabytes.my/servers/nvme-vps Checked 10 August 2026.

Sheet Capacity Check
A1: Capacity Check - Is 500 MB Really Enough?
A2: Not estimated. Our actual database schema was created in PostgreSQL 16 and filled with realistic Malaysian listing data, then measured.
B4: HOW THIS WAS MEASURED. Your migration files were applied to a real PostgreSQL 16 database. It was then loaded with 10,000 property listings, 30,000 leads, 15,000 contacts and 150,000 activity notes - using full-length Malaysian addresses, owner names, NRIC numbers and long free-text notes, so the row sizes are pessimistic rather than flattering. Indexes are included in every figure below. The whole thing came to 104 MB.
B6: 1. MEASURED SIZE PER RECORD (including indexes)
B7: Table | C7: Rows loaded | D7: Size on disk | E7: Bytes per row | F7: Share of 500 MB | G7: Comment
B8: Property listings | C8: 10000 | D8: 4.6 | E8: 485 | F8: =D8/500 -> 0.0092 | G8: Full title, address, price, size, owner name and phone.
B9: Leads | C9: 30000 | D9: 18 | E9: 620 | F9: =D9/500 -> 0.036 | G9: Includes marketing tracking fields and long referring web addresses.
B10: Contacts (clients) | C10: 15000 | D10: 9.1 | E10: 634 | F10: =D10/500 -> 0.0182 | G10: Includes NRIC number, occupation and a long free-text note.
B11: Activity notes | C11: 150000 | D11: 64 | E11: 449 | F11: =D11/500 -> 0.128 | G11: The largest table by far - a paragraph of notes on every call and viewing.
B12: Photo records (pointers only) | C12: 80000 | D12: 22 | E12: 294 | F12: =D12/500 -> 0.044 | G12: 80,000 photographs across 10,000 listings. The database holds only the file NAME - the images themselves are on Cloudflare R2.
B13: TOTAL DATABASE | D13: =SUM(D8:D12)+8 -> 125.7 | F13: =D13/500 -> 0.2514 | G13: Plus about 8 MB of PostgreSQL's own overhead. Measured total: 126 MB.
B15: 2. WHAT WE WILL ACTUALLY ACCUMULATE (blue cells are estimates - adjust them)
B16: Record type | C16: New per year | D16: Bytes each | E16: MB per year | F16: Comment
B17: Property listings | C17: 120 | D17: 485 | E17: =C17*D17/1048576 -> 0.055503845 | F17: Roughly two new listings per agent per month.
B18: Leads | C18: 3600 | D18: 620 | E18: =C18*D18/1048576 -> 2.1286011 | F18: About 60 enquiries per agent per month across all sources.
B19: Contacts (clients) | C19: 720 | D19: 634 | E19: =C19*D19/1048576 -> 0.43533325 | F19: Leads that convert - assumed one in five.
B20: Activity notes | C20: 36000 | D20: 449 | E20: =C20*D20/1048576 -> 15.415192 | F20: Ten notes per lead: calls, viewings, WhatsApp messages, follow-ups.
B21: Photo records (pointers only) | C21: 960 | D21: 294 | E21: =C21*D21/1048576 -> 0.26916504 | F21: Eight photographs per new listing. Only the file name is stored here.
B22: TOTAL GROWTH PER YEAR | E22: =SUM(E17:E21) -> 18.303795
B23: YEARS UNTIL 500 MB IS FULL | E23: =(500-8)/E22 -> 26.879672 | F23: At the rates above. Even at three times this activity it would still be over a decade.
B25: 3. THE PHOTOGRAPHS - A SEPARATE AND LARGER QUESTION
B26: Property photographs do NOT go into the Supabase database. They go to Cloudflare R2, which is a different service with its own allowance. This is the storage that actually grows quickly, so it is worth sizing properly.
B27: Measure | C27: Value | D27: Unit | F27: Comment
B28: Photographs per listing | C28: 8 | D28: photos | F28: Typical for a residential listing.
B29: Size per photograph after compression | C29: 0.5 | D29: MB | F29: A web-optimised image. Originals from a phone are far larger and should be resized on upload.
B30: Listings after 10 years | C30: =C17*10 -> 1200 | D30: listings | F30: From the growth table above.
B31: Total photo storage needed | C31: =C30*C28*C29/1024 -> 4.6875 | D31: GB
B32: Cloudflare R2 free allowance | C32: 10 | D32: GB | F32: Free forever, and no charge for downloads.
B33: Cost of the excess | C33: =MAX(0,C31-C32)*0.015*'Assumptions & Sources'!$C$6 -> 0
B35: VERDICT. 500 MB is not too small - it is roughly fifty times what the listings themselves need. Ten thousand property listings measured at 4.6 MB, which is under one per cent of the allowance. The database is dominated by activity notes, not listings, and even those take decades to fill it at a five-agent pace. Two honest caveats. First, the tighter free-plan constraint is the 500 MB of SHARED MEMORY, not the 500 MB of disk - memory affects how fast pages load, not how much we can store, and this application currently makes more database calls per page than it should (see the review findings). That is worth fixing whichever plan we are on. Second, photographs live on Cloudflare R2, not here, and they are the thing that genuinely grows - though at roughly one Ringgit a month for tens of gigabytes, it is not a wall we hit, just a line we start paying. So capacity is not a reason to leave the free plan. The absence of backups is.
B37: Measured 10 August 2026 on PostgreSQL 16 using the project's own migration files. R2 pricing: developers.cloudflare.com/r2/pricing. Supabase limits: supabase.com/pricing.
B39: 4. HOW THE PHOTOGRAPHS ACTUALLY FLOW (this is already how the system is built)
B40: Step | C40: What happens
B41: 1. Agent uploads a photo | C41: The file goes straight to Cloudflare R2 object storage. It never enters the database.
B42: 2. Database records a pointer | C42: Only the file name and its location are stored - measured at 294 bytes per photograph, against roughly 500,000 bytes for the image itself. That is about 1,700 times smaller.
B43: 3. Agent opens a listing | C43: The page returns a temporary, signed web address for each photograph, valid for one hour.
B44: 4. Browser fetches the image | C44: The browser downloads directly from Cloudflare - the image never passes through our application server. Our hosting bandwidth is untouched, and Cloudflare charges nothing for downloads.
B46: WHY THIS MATTERS TO THE DECISION. Because images bypass the application entirely, photograph traffic does not consume hosting bandwidth on any option, and the 500 MB database limit is essentially unrelated to how many photographs we hold. It is the single biggest reason a small free database is workable for a property business. The exception is OPTION D. If client data must stay in Malaysia, photographs move off Cloudflare and onto our own server - at which point they consume our disk, our bandwidth and our backup space, and every image request goes through our machine instead of Cloudflare's network. That is a genuine and often-overlooked cost of choosing residency, and it is why Option D should be sized with 100 GB rather than the cheaper 30 GB local plans.

Sheet Data Residency Options
A1: Data Residency - Singapore versus Malaysia
A2: What changes, and what it costs, if client information may not leave Malaysia.
B4: The CRM stores client identity-card and passport numbers. Under the Malaysian Personal Data Protection Act, transferring personal data outside Malaysia carries conditions. Options A to C place that data in Singapore; Option D keeps everything inside Malaysia. This tab sets out the practical and cost difference. It is a flag for professional advice, not a legal opinion.
B6: WHAT HAS TO CHANGE
B7: Element | C7: Options A - C (Singapore) | D7: Option D (Malaysia only) (recommended) | E7: Consequence
B8: Database | C8: Supabase managed, Singapore | D8: PostgreSQL we run in Malaysia | E8: No managed provider offers a Malaysia region - Supabase's only Southeast Asia region is Singapore. Choosing Malaysia therefore means self-hosting. There is no managed shortcut.
B9: Application hosting | C9: Vercel or Cloudflare | D9: Same Malaysian server | E9: Loses automatic scaling and the vendor's deployment tooling.
B10: Property photographs | C10: Cloudflare R2 (free, overseas) | D10: Local server disk | E10: Photographs are personal data once tied to a client record. 100 GB is included on the proposed plan.
B11: Backups | C11: Cloudflare R2, free allowance | D11: Second Malaysian location | E11: The item most often forgotten. A backup sitting overseas defeats the residency requirement entirely.
B12: Email delivery | C12: Resend (overseas) | D12: Local SMTP, or accept overseas | E12: Message content and recipient addresses pass through the provider. Worth confirming whether this is in scope.
B13: Error monitoring | C13: Sentry (overseas) | D13: Disable, or self-host | E13: Diagnostic data can contain personal information. Simplest answer is to strip it before sending.
B15: MALAYSIAN HOSTING PROVIDERS SURVEYED
B16: Provider / plan | C16: Specification | D16: MYR per month | E16: Comment
B17: Shinjiru Budget VPS | C17: 1 vCPU, 1 GB RAM, 30 GB SSD | D17: 49 | E17: Cheapest local option, but 1 GB RAM cannot run the application and database together.
B18: Exabytes NVMe C1 | C18: 1 vCPU, 4 GB RAM, 50 GB NVMe | D18: 45 | E18: Good value, single core. Workable but tight during deployments.
B19: Exabytes NVMe C2 | C19: 2 vCPU, 4 GB RAM, 100 GB NVMe | D19: 60 | E19: RECOMMENDED for Option D. Comfortable for application, database and photographs. Tier-3 datacentre.
B20: VPS Malaysia Plan 1 | C20: 1 vCPU, 1 GB RAM, 30 GB SSD | D20: 59 | E20: Underpowered for this workload.
B21: ServerFreak Starter | C21: 1 vCPU, 1 GB RAM, 30 GB SSD | D21: 75 | E21: Underpowered for the price.
B22: AWS Asia Pacific (Malaysia) | C22: Comparable managed instance | D22: see note | E22: A Malaysian AWS region exists and would satisfy residency with enterprise tooling, but costs several times a local server and adds complexity. Revisit only if the agency grows substantially.
B24: COST OF CHOOSING MALAYSIA
B25: Measure | C25: Option A (Singapore) | D25: Option D (Malaysia) | E25: Difference
B26: Cash - MYR per month | C26: ='Cost Comparison'!D14 -> 102 | D26: ='Cost Comparison'!G14 -> 92 | E26: =D26-C26 -> -10
B27: Cash - MYR per year | C27: ='Cost Comparison'!D15 -> 1224 | D27: ='Cost Comparison'!G15 -> 1104 | E27: =D27-C27 -> -120
B28: Cash - MYR over three years | C28: ='Cost Comparison'!D16 -> 3672 | D28: ='Cost Comparison'!G16 -> 3312 | E28: =D28-C28 -> -360
B30: Reading of it: keeping data in Malaysia costs nothing extra - Option D is in fact about RM 120 a year cheaper than Option A, because a Malaysian server replaces the hosting subscription. The trade-off is not money. No provider offers a managed Malaysia region, so backups, patching and uptime stop being a vendor's responsibility and become ours. If residency is a genuine requirement, or a corporate client is likely to ask, Option D is affordable and worth doing properly.

Sheet Implementation Plan
A1: Implementation Plan
A2: The order of work. Sequenced so each phase reduces the risk of the next.
B4: Phase | C4: Deliverable | D4: Priority | E4: What it addresses, and why it sits here in the order
B5: Phase 0 | C5: Unbreak the build | D5: Critical | E5: The dependency list and lockfile disagree, so a clean install or automated deployment fails before the code compiles. Nothing can ship until this is fixed.
B6: Phase 1 | C6: Close security gaps | D6: Critical | E6: Four verified issues, including a public endpoint open to the internet and any agent being able to view any client's identity-card number. Must be done before more client data is entered.
B7: Phase 2 | C7: Move database to PostgreSQL | D7: High | E7: Removes the current database vendor. Only one file changes - the code was written to isolate it. Also gives proper database transactions, which Phase 4 depends on.
B8: Phase 3 | C8: Replace Clerk with Better Auth | D8: High | E8: Removes the authentication vendor and its per-user pricing risk. Database-held sessions also close the gap where departed staff keep access.
B9: Phase 4 | C9: Fix data-loss and accuracy faults | D9: High | E9: Duplicate client records, repeat enquiries silently discarded, bulk imports rejecting properly formatted rows. Needs the transactions from Phase 2.
B10: Phase 5 | C10: Operations and compliance | D10: Medium | E10: Schedules the 24-month PDPA purge, which exists but runs nowhere today. Adds start-up configuration checks and database indexes.
B11: Phase 6 | C11: Finalise hosting and deploy | D11: Medium | E11: Implement whichever option is approved.
B12: Ongoing | C12: Automated test coverage | D12: Medium | E12: Four of the Phase 4 faults would have been caught automatically. Reduces the chance of repeat incidents.
B14: EXTRA SETUP STEP BY HOSTING OPTION
B15: Option | C15: Additional work required
B16: Option A | C16: Managed platform - deploy and configure only. Nothing further.
B17: Option B | C17: Repair the Cloudflare deployment configuration, which is currently incomplete.
B18: Option C | C18: Provision the Singapore server, harden it, install PostgreSQL, and build and test backups.
B19: Option D | C19: As Option C, plus move photographs to local storage and arrange a Malaysian backup target.
B21: Phases 0 and 1 are not cost-saving work - they close a live data-exposure gap and a broken build, and are recommended whichever hosting option is approved. Phases 2 and 3 are what remove the two paid service vendors.

Sheet Risks & Findings
A1: Risks & Findings
A2: From a full review of the source code on 10 August 2026. Each finding was verified against the code, not assumed.
B4: Ref | C4: Finding | D4: Severity | E4: Business impact | F4: Addressed in
B5: R1 | C5: Public web-form endpoint is unauthenticated | D5: Critical | E5: Anyone on the internet can create leads, trigger WhatsApp messages to our agents, and record PDPA consent for people who never gave it. It also reveals whether a phone number already belongs to a client. | F5: Phase 1
B6: R2 | C6: Any agent can open any client's record | D6: Critical | E6: By changing the address in the browser, an agent can view any client's identity-card or passport number, budget and private notes - including other agents' clients. | F6: Phase 1
B7: R3 | C7: Departed staff keep data-export access | D7: High | E7: Deactivating a user does not end their existing session, so a former administrator can still download a complete client data file. | F7: Phase 1 / 3
B8: R4 | C8: Document deletion skips its permission check | D8: High | E8: In certain conditions any logged-in user can permanently delete stored client documents. | F8: Phase 1
B9: R5 | C9: Build fails on a clean installation | D9: High | E9: The dependency list and lockfile disagree, so automated deployment fails before compiling. Releases are blocked. | F9: Phase 0
B10: R6 | C10: Repeat enquiries silently discarded | D10: High | E10: A past client making a new enquiry is matched to their old closed record. The new enquiry is never created and never assigned. Lost business, with no trace that it happened. | F10: Phase 4
B11: R7 | C11: Duplicate client records created | D11: Medium | E11: Converting a lead twice - an ordinary double-click - creates two records for one person and distorts agent performance figures. | F11: Phase 4
B12: R8 | C12: Bulk import rejects valid rows | D12: Medium | E12: A budget entered as 1,200,000 or 'RM 850000' causes the whole row to be rejected, name and phone included. Staff lose data during import. | F12: Phase 4
B13: R9 | C13: PDPA 24-month purge not scheduled | D13: Medium | E13: The deletion routine was written but nothing runs it, so the retention obligation is not currently being met. | F13: Phase 5
B14: R10 | C14: Hosting licence breach | D14: Medium | E14: The free hosting tier in use is licensed for non-commercial personal use only. Continued business use breaches those terms. | F14: Phase 6
B15: R11 | C15: Error monitoring is inert | D15: Low | E15: The monitoring service is installed but never started, so faults in live use are discarded rather than reported. | F15: Phase 5
... B18: R13 | C18: Cross-border data residency | D18: Decision | E18: Client identity numbers would sit in Singapore under Options A to C. Option D keeps everything in Malaysia. See the Data Residency tab. Flagged for professional advice. | F18: Management
C20: Critical and High findings | D20: =COUNTIF(D5:D17,"Critical")+COUNTIF(D5:D17,"High") -> 7

Sheet Assumptions & Sources
A1: Assumptions, Inputs & Sources
A2: All costs in Malaysian Ringgit. Blue cells are inputs - change them and the whole workbook recalculates.
B4: INPUTS
B5: Input | C5: Value | D5: Basis / note
B6: USD to MYR exchange rate | C6: 4.75 | D6: Indicative. Update to your bank's rate on the day of the proposal. Services priced in US dollars are converted at this rate.
B7: Number of staff | C7: 5 | D7: Current agency headcount.
B9: PRICING SOURCES (checked 10 August 2026)
B10: Item | C10: List price | D10: Source and notes
B11: Supabase Free tier (Singapore) | C11: USD 0 | D11: 500 MB database, 1 GB file storage, 5 GB egress, 50k users, 7-day backup snapshot. Singapore is the only Southeast Asia region - there is no Malaysia region. Projects pause after 7 days of no activity; a daily-use CRM will not pause. Sources: itpathsolutions.com/supabase-free-tier-limits ; supabase.com/docs/guides/platform/regions
B12: Supabase Pro | C12: USD 25 / mth | D12: Only if free-tier limits are exceeded. Adds daily backups and removes the pause.
B13: Vercel Hobby | C13: USD 0 | D13: LICENCE RISK - restricted to non-commercial personal use only. Not valid for a business system. Source: supadrop.host/blog/vercel-pricing-free-tier-limits/
B14: Vercel Pro | C14: USD 20 / seat / mth | D14: Charged per deploying seat, not per agent. One seat assumed.
B15: Cloudflare Workers Paid | C15: USD 5 / mth | D15: 10M requests and 30M CPU-ms included. The free tier caps CPU at 10 ms per request, too tight for this application. Source: developers.cloudflare.com/workers/platform/pricing/
B16: VPS - Singapore, 2 GB | C16: USD 12 / mth | D16: DigitalOcean SGP1 or Vultr Singapore, roughly 15-20 ms from Kuala Lumpur. Source: cloudmart.dev/blog/cheapest-vps-2026
B17: VPS - Malaysia, 4 GB (Exabytes C2) | C17: RM 60 / mth | D17: 2 vCPU, 4 GB RAM, 100 GB NVMe, 4 TB transfer, Tier-3 datacentre in Malaysia. Local alternatives: Shinjiru RM 49, VPS Malaysia RM 59, ServerFreak RM 75 - all 1 GB RAM, too small for this workload. Source: exabytes.my/servers/nvme-vps ; onedollarvps.com/locations/vps-in-malaysia
B18: Malaysian off-site backup storage | C18: RM 25 / mth | D18: ESTIMATE. Required only under Option D, because the free Cloudflare backup target sits outside Malaysia.
B19: Cloudflare R2 object storage | C19: USD 0 | D19: 10 GB free, no egress charges. Already in use for property photographs.
B20: Better Auth (replaces Clerk) | C20: USD 0 | D20: MIT licence, self-hosted, no per-user charge. Source: better-auth.com/blog/authjs-joins-better-auth
B21: Resend email / Sentry monitoring | C21: USD 0 | D21: Free tiers sufficient at this volume.
... B23: Domain name | C23: RM 7 / mth | D23: Approximate existing cost, unchanged by this proposal.
B25: SCOPE NOTES
B26: - All figures are in Malaysian Ringgit. Services priced in US dollars convert at the exchange rate above, so totals move with the rate.
B27: - This workbook covers tools and services only - hosting, database, storage and related subscriptions. Internal development effort is deliberately excluded.
B28: - Technical findings come from a full review of the source code on 10 August 2026, verified by running the build and dependency tooling.
B29: - This workbook is a planning aid. The PDPA data-residency question should be confirmed with a qualified adviser; nothing here is legal advice.
B31: - Supabase free plan: commercial use is permitted (no restriction in their terms or pricing page), but it includes no backups and no SLA. Supabase's own documentation advises free-plan users to export their data regularly. Source: supabase.com/pricing ; supabase.com/docs/guides/platform/backups
